/scratch/mp5847/conda_environments/conda_pkgs/diffusion_ft/lib/python3.10/site-packages/torch/distributed/launch.py:181: FutureWarning: The module torch.distributed.launch is deprecated
and will be removed in future. Use torchrun.
Note that --use-env is set by default in torchrun.
If your script expects `--local-rank` argument to be set, please
change it to read from `os.environ['LOCAL_RANK']` instead. See 
https://pytorch.org/docs/stable/distributed.html#launch-utility for 
further instructions

  warnings.warn(
WARNING:torch.distributed.run:
*****************************************
Setting OMP_NUM_THREADS environment variable for each process to be 1 in default, to avoid your system being overloaded, please further tune the variable for optimal performance in your application as needed. 
*****************************************
/scratch/mp5847/conda_environments/conda_pkgs/diffusion_ft/bin/python: can't open file '/vast/mp5847/minimal-diffusion/scripts/main.py': [Errno 2] No such file or directory
/scratch/mp5847/conda_environments/conda_pkgs/diffusion_ft/bin/python: can't open file '/vast/mp5847/minimal-diffusion/scripts/main.py': [Errno 2] No such file or directory
/scratch/mp5847/conda_environments/conda_pkgs/diffusion_ft/bin/python: can't open file '/vast/mp5847/minimal-diffusion/scripts/main.py': [Errno 2] No such file or directory
/scratch/mp5847/conda_environments/conda_pkgs/diffusion_ft/bin/python: can't open file '/vast/mp5847/minimal-diffusion/scripts/main.py': [Errno 2] No such file or directory
ERROR:torch.distributed.elastic.multiprocessing.api:failed (exitcode: 2) local_rank: 0 (pid: 1142038) of binary: /scratch/mp5847/conda_environments/conda_pkgs/diffusion_ft/bin/python
Traceback (most recent call last):
  File "/scratch/mp5847/conda_environments/conda_pkgs/diffusion_ft/lib/python3.10/runpy.py", line 196, in _run_module_as_main
    return _run_code(code, main_globals, None,
  File "/scratch/mp5847/conda_environments/conda_pkgs/diffusion_ft/lib/python3.10/runpy.py", line 86, in _run_code
    exec(code, run_globals)
  File "/scratch/mp5847/conda_environments/conda_pkgs/diffusion_ft/lib/python3.10/site-packages/torch/distributed/launch.py", line 196, in <module>
    main()
  File "/scratch/mp5847/conda_environments/conda_pkgs/diffusion_ft/lib/python3.10/site-packages/torch/distributed/launch.py", line 192, in main
    launch(args)
  File "/scratch/mp5847/conda_environments/conda_pkgs/diffusion_ft/lib/python3.10/site-packages/torch/distributed/launch.py", line 177, in launch
    run(args)
  File "/scratch/mp5847/conda_environments/conda_pkgs/diffusion_ft/lib/python3.10/site-packages/torch/distributed/run.py", line 785, in run
    elastic_launch(
  File "/scratch/mp5847/conda_environments/conda_pkgs/diffusion_ft/lib/python3.10/site-packages/torch/distributed/launcher/api.py", line 134, in __call__
    return launch_agent(self._config, self._entrypoint, list(args))
  File "/scratch/mp5847/conda_environments/conda_pkgs/diffusion_ft/lib/python3.10/site-packages/torch/distributed/launcher/api.py", line 250, in launch_agent
    raise ChildFailedError(
torch.distributed.elastic.multiprocessing.errors.ChildFailedError: 
============================================================
main.py FAILED
------------------------------------------------------------
Failures:
[1]:
  time      : 2023-11-24_17:29:29
  host      : ga033.hpc.nyu.edu
  rank      : 1 (local_rank: 1)
  exitcode  : 2 (pid: 1142039)
  error_file: <N/A>
  traceback : To enable traceback see: https://pytorch.org/docs/stable/elastic/errors.html
[2]:
  time      : 2023-11-24_17:29:29
  host      : ga033.hpc.nyu.edu
  rank      : 2 (local_rank: 2)
  exitcode  : 2 (pid: 1142040)
  error_file: <N/A>
  traceback : To enable traceback see: https://pytorch.org/docs/stable/elastic/errors.html
[3]:
  time      : 2023-11-24_17:29:29
  host      : ga033.hpc.nyu.edu
  rank      : 3 (local_rank: 3)
  exitcode  : 2 (pid: 1142041)
  error_file: <N/A>
  traceback : To enable traceback see: https://pytorch.org/docs/stable/elastic/errors.html
------------------------------------------------------------
Root Cause (first observed failure):
[0]:
  time      : 2023-11-24_17:29:29
  host      : ga033.hpc.nyu.edu
  rank      : 0 (local_rank: 0)
  exitcode  : 2 (pid: 1142038)
  error_file: <N/A>
  traceback : To enable traceback see: https://pytorch.org/docs/stable/elastic/errors.html
============================================================
